Workbook
Name Sistemas_de_enfriamiento_de_agua: [1]Incidentes!#REF!
Name Slicer_Área: #N/A
Name Slicer_Estatus: #N/A
Name Slicer_Mecanismo_de_lesión__Ligar_tabla: #N/A
Name Slicer_Peligros_identificados: #N/A
Name Slicer_Piramide_de_Contramedidas: #N/A
Name Slicer_Planta: #N/A
Name Slicer_Planta1: #N/A
Name Slicer_Tiempo_de_acción: #N/A

Sheet Dashboard
J8: 15 | K8: Certero | L8: =COUNTIFS(#REF!,15,#REF!,0.1) -> #REF! | M8: =COUNTIFS(#REF!,15,#REF!,0.5) -> #REF! | N8: =COUNTIFS(#REF!,15,#REF!,1) -> #REF! | O8: =COUNTIFS(#REF!,15,#REF!,2) -> #REF! | P8: =COUNTIFS(#REF!,15,#REF!,4) -> #REF! | Q8: =COUNTIFS(#REF!,15,#REF!,8) -> #REF! | R8: =COUNTIFS(#REF!,15,#REF!,15) -> #REF!
J9: 10 | K9: Muy probable | L9: =COUNTIFS(#REF!,10,#REF!,0.1) -> #REF! | M9: =COUNTIFS(#REF!,10,#REF!,0.5) -> #REF! | N9: =COUNTIFS(#REF!,10,#REF!,1) -> #REF! | O9: =COUNTIFS(#REF!,10,#REF!,2) -> #REF! | P9: =COUNTIFS(#REF!,10,#REF!,4) -> #REF! | Q9: =COUNTIFS(#REF!,10,#REF!,8) -> #REF! | R9: =COUNTIFS(#REF!,10,#REF!,15) -> #REF!
J10: 8 | K10: Probable | L10: =COUNTIFS(#REF!,8,#REF!,0.1) -> #REF! | M10: =COUNTIFS(#REF!,8,#REF!,0.5) -> #REF! | N10: =COUNTIFS(#REF!,8,#REF!,1) -> #REF! | O10: =COUNTIFS(#REF!,8,#REF!,2) -> #REF! | P10: =COUNTIFS(#REF!,8,#REF!,4) -> #REF! | Q10: =COUNTIFS(#REF!,8,#REF!,8) -> #REF! | R10: =COUNTIFS(#REF!,8,#REF!,15) -> #REF!
J11: 5 | K11: Alguna probabilidad | L11: =COUNTIFS(#REF!,5,#REF!,0.1) -> #REF! | M11: =COUNTIFS(#REF!,5,#REF!,0.5) -> #REF! | N11: =COUNTIFS(#REF!,5,#REF!,1) -> #REF! | O11: =COUNTIFS(#REF!,5,#REF!,2) -> #REF! | P11: =COUNTIFS(#REF!,5,#REF!,4) -> #REF! | Q11: =COUNTIFS(#REF!,5,#REF!,8) -> #REF! | R11: =COUNTIFS(#REF!,5,#REF!,15) -> #REF!
J12: 2 | K12: Posible | L12: =COUNTIFS(#REF!,2,#REF!,0.1) -> #REF! | M12: =COUNTIFS(#REF!,2,#REF!,0.5) -> #REF! | N12: =COUNTIFS(#REF!,2,#REF!,1) -> #REF! | O12: =COUNTIFS(#REF!,2,#REF!,2) -> #REF! | P12: =COUNTIFS(#REF!,2,#REF!,4) -> #REF! | Q12: =COUNTIFS(#REF!,2,#REF!,8) -> #REF! | R12: =COUNTIFS(#REF!,2,#REF!,15) -> #REF!
J13: 1 | K13: Improbable | L13: =COUNTIFS(#REF!,1,#REF!,0.1) -> #REF! | M13: =COUNTIFS(#REF!,1,#REF!,0.5) -> #REF! | N13: =COUNTIFS(#REF!,1,#REF!,1) -> #REF! | O13: =COUNTIFS(#REF!,1,#REF!,2) -> #REF! | P13: =COUNTIFS(#REF!,1,#REF!,4) -> #REF! | Q13: =COUNTIFS(#REF!,1,#REF!,8) -> #REF! | R13: =COUNTIFS(#REF!,1,#REF!,15) -> #REF!
J14: 0.5 | K14: Altamente improbable | L14: =COUNTIFS(#REF!,0.5,#REF!,0.1) -> #REF! | M14: =COUNTIFS(#REF!,0.5,#REF!,0.5) -> #REF! | N14: =COUNTIFS(#REF!,0.5,#REF!,1) -> #REF! | O14: =COUNTIFS(#REF!,0.5,#REF!,2) -> #REF! | P14: =COUNTIFS(#REF!,0.5,#REF!,4) -> #REF! | Q14: =COUNTIFS(#REF!,0.5,#REF!,8) -> #REF! | R14: =COUNTIFS(#REF!,0.5,#REF!,15) -> #REF!
J15: 0.1 | K15: Casi imposible | L15: =COUNTIFS(#REF!,0.1,#REF!,0.1) -> #REF! | M15: =COUNTIFS(#REF!,0.1,#REF!,0.5) -> #REF! | N15: =COUNTIFS(#REF!,0.1,#REF!,1) -> #REF! | O15: =COUNTIFS(#REF!,0.1,#REF!,2) -> #REF! | P15: =COUNTIFS(#REF!,0.1,#REF!,4) -> #REF! | Q15: =COUNTIFS(#REF!,0.1,#REF!,8) -> #REF! | R15: =COUNTIFS(#REF!,0.1,#REF!,15) -> #REF!
J16: 0 | K16: Imposible | L16: =COUNTIFS(#REF!,0,#REF!,0.1) -> #REF! | M16: =COUNTIFS(#REF!,0,#REF!,0.5) -> #REF! | N16: =COUNTIFS(#REF!,0,#REF!,1) -> #REF! | O16: =COUNTIFS(#REF!,0,#REF!,2) -> #REF! | P16: =COUNTIFS(#REF!,0,#REF!,4) -> #REF! | Q16: =COUNTIFS(#REF!,0,#REF!,8) -> #REF! | R16: =COUNTIFS(#REF!,0,#REF!,15) -> #REF!
L17: Rasguño o raspadura | M17: Cortadura o efecto leve a la salud | N17: Fractura de hueso menor (dedos) o enfermedad ocupacional menor temporal | O17: Fractura de hueso mayor (brazo, pierna) o enfermedad ocupacional menor permanente | P17: Pérdida de un ojo, un dedo o enfermedad ocupacional seria temporal (LTA) | Q17: Pérdida de los dos ojos, manos, piernas o enfermedad ocupacional seria permanente | R17: Muerte
L18: 0.1 | M18: 0.5 | N18: 1 | O18: 2 | P18: 4 | Q18: 8 | R18: 15
T20: Descripación | U20: Fecha programada | V20: Total
T21: Row Labels | U21: Sum of Fecha programada
T22: Tarea 52 | U22: 45397
T23: Tarea 56 | U23: 45397
T24: Tarea 7 | U24: 45397
T25: Tarea 60 | U25: 45397
T26: Tarea 9 | U26: 45397
T27: Tarea 64 | U27: 45397
T28: Tarea 11 | U28: 45397
T29: Tarea 68 | U29: 45397
T30: Tarea 8 | U30: 45397
T31: Tarea 76 | U31: 45397
T32: Tarea 6 | U32: 45397
T33: Tarea 84 | U33: 45397
... T36: Grand Total | U36: 635558
A58: .

Sheet Matriz
A1: Planta | B1: Gravedad (Actual) | C1: Valor GA | D1: Probabilidad (Actual) | E1: Valor PA | G1: =A1 -> Planta | H1: =B1 -> Gravedad (Actual) | I1: =C1 -> Valor GA | J1: =D1 -> Probabilidad (Actual) | K1: =E1 -> Valor PA
A2: =#REF! -> #REF! | B2: =#REF! -> #REF! | C2: =#REF! -> #REF! | D2: =#REF! -> #REF! | E2: =#REF! -> #REF! | G2: =A2 -> #REF! | H2: =B2 -> #REF! | I2: =C2 -> #REF! | J2: =D2 -> #REF! | K2: =E2 -> #REF! | S2: Certero | T2: =COUNTIFS(#REF!,15,#REF!,0.1) -> #REF! | U2: =COUNTIFS(#REF!,15,#REF!,0.5) -> #REF! | V2: =COUNTIFS(#REF!,15,#REF!,1) -> #REF! | W2: =COUNTIFS(#REF!,15,#REF!,2) -> #REF! | X2: =COUNTIFS(#REF!,15,#REF!,4) -> #REF! | Y2: =COUNTIFS(#REF!,15,#REF!,8) -> #REF! | Z2: =COUNTIFS(#REF!,15,#REF!,15) -> #REF!
A3: =#REF! -> #REF! | B3: =#REF! -> #REF! | C3: =#REF! -> #REF! | D3: =#REF! -> #REF! | E3: =#REF! -> #REF! | G3: =A3 -> #REF! | H3: =B3 -> #REF! | I3: =C3 -> #REF! | J3: =D3 -> #REF! | K3: =E3 -> #REF! | S3: Muy probable | T3: =COUNTIFS(#REF!,10,#REF!,0.1) -> #REF! | U3: =COUNTIFS(#REF!,10,#REF!,0.5) -> #REF! | V3: =COUNTIFS(#REF!,10,#REF!,1) -> #REF! | W3: =COUNTIFS(#REF!,10,#REF!,2) -> #REF! | X3: =COUNTIFS(#REF!,10,#REF!,4) -> #REF! | Y3: =COUNTIFS(#REF!,10,#REF!,8) -> #REF! | Z3: =COUNTIFS(#REF!,10,#REF!,15) -> #REF!
A4: =#REF! -> #REF! | B4: =#REF! -> #REF! | C4: =#REF! -> #REF! | D4: =#REF! -> #REF! | E4: =#REF! -> #REF! | G4: =A4 -> #REF! | H4: =B4 -> #REF! | I4: =C4 -> #REF! | J4: =D4 -> #REF! | K4: =E4 -> #REF! | S4: Probable | T4: =COUNTIFS(#REF!,8,#REF!,0.1) -> #REF! | U4: =COUNTIFS(#REF!,8,#REF!,0.5) -> #REF! | V4: =COUNTIFS(#REF!,8,#REF!,1) -> #REF! | W4: =COUNTIFS(#REF!,8,#REF!,2) -> #REF! | X4: =COUNTIFS(#REF!,8,#REF!,4) -> #REF! | Y4: =COUNTIFS(#REF!,8,#REF!,8) -> #REF! | Z4: =COUNTIFS(#REF!,8,#REF!,15) -> #REF!
A5: =#REF! -> #REF! | B5: =#REF! -> #REF! | C5: =#REF! -> #REF! | D5: =#REF! -> #REF! | E5: =#REF! -> #REF! | G5: =A5 -> #REF! | H5: =B5 -> #REF! | I5: =C5 -> #REF! | J5: =D5 -> #REF! | K5: =E5 -> #REF! | S5: Alguna probabilidad | T5: =COUNTIFS(#REF!,5,#REF!,0.1) -> #REF! | U5: =COUNTIFS(#REF!,5,#REF!,0.5) -> #REF! | V5: =COUNTIFS(#REF!,5,#REF!,1) -> #REF! | W5: =COUNTIFS(#REF!,5,#REF!,2) -> #REF! | X5: =COUNTIFS(#REF!,5,#REF!,4) -> #REF! | Y5: =COUNTIFS(#REF!,5,#REF!,8) -> #REF! | Z5: =COUNTIFS(#REF!,5,#REF!,15) -> #REF!
A6: =#REF! -> #REF! | B6: =#REF! -> #REF! | C6: =#REF! -> #REF! | D6: =#REF! -> #REF! | E6: =#REF! -> #REF! | G6: =A6 -> #REF! | H6: =B6 -> #REF! | I6: =C6 -> #REF! | J6: =D6 -> #REF! | K6: =E6 -> #REF! | S6: Posible | T6: =COUNTIFS(#REF!,2,#REF!,0.1) -> #REF! | U6: =COUNTIFS(#REF!,2,#REF!,0.5) -> #REF! | V6: =COUNTIFS(#REF!,2,#REF!,1) -> #REF! | W6: =COUNTIFS(#REF!,2,#REF!,2) -> #REF! | X6: =COUNTIFS(#REF!,2,#REF!,4) -> #REF! | Y6: =COUNTIFS(#REF!,2,#REF!,8) -> #REF! | Z6: =COUNTIFS(#REF!,2,#REF!,15) -> #REF!
A7: =#REF! -> #REF! | B7: =#REF! -> #REF! | C7: =#REF! -> #REF! | D7: =#REF! -> #REF! | E7: =#REF! -> #REF! | G7: =A7 -> #REF! | H7: =B7 -> #REF! | I7: =C7 -> #REF! | J7: =D7 -> #REF! | K7: =E7 -> #REF! | S7: Improbable | T7: =COUNTIFS(#REF!,1,#REF!,0.1) -> #REF! | U7: =COUNTIFS(#REF!,1,#REF!,0.5) -> #REF! | V7: =COUNTIFS(#REF!,1,#REF!,1) -> #REF! | W7: =COUNTIFS(#REF!,1,#REF!,2) -> #REF! | X7: =COUNTIFS(#REF!,1,#REF!,4) -> #REF! | Y7: =COUNTIFS(#REF!,1,#REF!,8) -> #REF! | Z7: =COUNTIFS(#REF!,1,#REF!,15) -> #REF!
A8: =#REF! -> #REF! | B8: =#REF! -> #REF! | C8: =#REF! -> #REF! | D8: =#REF! -> #REF! | E8: =#REF! -> #REF! | G8: =A8 -> #REF! | H8: =B8 -> #REF! | I8: =C8 -> #REF! | J8: =D8 -> #REF! | K8: =E8 -> #REF! | S8: Altamente improbable | T8: =COUNTIFS(#REF!,0.5,#REF!,0.1) -> #REF! | U8: =COUNTIFS(#REF!,0.5,#REF!,0.5) -> #REF! | V8: =COUNTIFS(#REF!,0.5,#REF!,1) -> #REF! | W8: =COUNTIFS(#REF!,0.5,#REF!,2) -> #REF! | X8: =COUNTIFS(#REF!,0.5,#REF!,4) -> #REF! | Y8: =COUNTIFS(#REF!,0.5,#REF!,8) -> #REF! | Z8: =COUNTIFS(#REF!,0.5,#REF!,15) -> #REF!
A9: =#REF! -> #REF! | B9: =#REF! -> #REF! | C9: =#REF! -> #REF! | D9: =#REF! -> #REF! | E9: =#REF! -> #REF! | G9: =A9 -> #REF! | H9: =B9 -> #REF! | I9: =C9 -> #REF! | J9: =D9 -> #REF! | K9: =E9 -> #REF! | S9: Casi imposible | T9: =COUNTIFS(#REF!,0.1,#REF!,0.1) -> #REF! | U9: =COUNTIFS(#REF!,0.1,#REF!,0.5) -> #REF! | V9: =COUNTIFS(#REF!,0.1,#REF!,1) -> #REF! | W9: =COUNTIFS(#REF!,0.1,#REF!,2) -> #REF! | X9: =COUNTIFS(#REF!,0.1,#REF!,4) -> #REF! | Y9: =COUNTIFS(#REF!,0.1,#REF!,8) -> #REF! | Z9: =COUNTIFS(#REF!,0.1,#REF!,15) -> #REF!
A10: =#REF! -> #REF! | B10: =#REF! -> #REF! | C10: =#REF! -> #REF! | D10: =#REF! -> #REF! | E10: =#REF! -> #REF! | G10: =A10 -> #REF! | H10: =B10 -> #REF! | I10: =C10 -> #REF! | J10: =D10 -> #REF! | K10: =E10 -> #REF! | S10: Imposible | T10: =COUNTIFS(Table2[Valor PA],0,Table2[Valor GA],0.1) -> 0 | U10: =COUNTIFS(#REF!,0,#REF!,0.5) -> #REF! | V10: =COUNTIFS(#REF!,0,#REF!,1) -> #REF! | W10: =COUNTIFS(#REF!,0,#REF!,2) -> #REF! | X10: =COUNTIFS(#REF!,0,#REF!,4) -> #REF! | Y10: =COUNTIFS(#REF!,0,#REF!,8) -> #REF! | Z10: =COUNTIFS(#REF!,0,#REF!,15) -> #REF!
A11: =#REF! -> #REF! | B11: =#REF! -> #REF! | C11: =#REF! -> #REF! | D11: =#REF! -> #REF! | E11: =#REF! -> #REF! | G11: =A11 -> #REF! | H11: =B11 -> #REF! | I11: =C11 -> #REF! | J11: =D11 -> #REF! | K11: =E11 -> #REF! | T11: Rasguño o raspadura | U11: Cortadura o efecto leve a la salud | V11: Fractura de hueso menor (dedos) o enfermedad ocupacional menor temporal | W11: Fractura de hueso mayor (brazo, pierna) o enfermedad ocupacional menor permanente | X11: Pérdida de un ojo, un dedo o enfermedad ocupacional seria temporal (LTA) | Y11: Pérdida de los dos ojos, manos, piernas o enfermedad ocupacional seria permanente | Z11: Muerte
A12: =#REF! -> #REF! | B12: =#REF! -> #REF! | C12: =#REF! -> #REF! | D12: =#REF! -> #REF! | E12: =#REF! -> #REF! | G12: =A12 -> #REF! | H12: =B12 -> #REF! | I12: =C12 -> #REF! | J12: =D12 -> #REF! | K12: =E12 -> #REF! | T12: 0.1 | U12: 0.5 | V12: 1 | W12: 2 | X12: 4 | Y12: 8 | Z12: 15
A13: =#REF! -> #REF! | B13: =#REF! -> #REF! | C13: =#REF! -> #REF! | D13: =#REF! -> #REF! | E13: =#REF! -> #REF! | G13: =A13 -> #REF! | H13: =B13 -> #REF! | I13: =C13 -> #REF! | J13: =D13 -> #REF! | K13: =E13 -> #REF!
A14: =#REF! -> #REF! | B14: =#REF! -> #REF! | C14: =#REF! -> #REF! | D14: =#REF! -> #REF! | E14: =#REF! -> #REF! | G14: =A14 -> #REF! | H14: =B14 -> #REF! | I14: =C14 -> #REF! | J14: =D14 -> #REF! | K14: =E14 -> #REF!
A15: =#REF! -> #REF! | B15: =#REF! -> #REF! | C15: =#REF! -> #REF! | D15: =#REF! -> #REF! | E15: =#REF! -> #REF! | G15: =A15 -> #REF! | H15: =B15 -> #REF! | I15: =C15 -> #REF! | J15: =D15 -> #REF! | K15: =E15 -> #REF!
A16: =#REF! -> #REF! | B16: =#REF! -> #REF! | C16: =#REF! -> #REF! | D16: =#REF! -> #REF! | E16: =#REF! -> #REF! | G16: =A16 -> #REF! | H16: =B16 -> #REF! | I16: =C16 -> #REF! | J16: =D16 -> #REF! | K16: =E16 -> #REF!
A17: =#REF! -> #REF! | B17: =#REF! -> #REF! | C17: =#REF! -> #REF! | D17: =#REF! -> #REF! | E17: =#REF! -> #REF! | G17: =A17 -> #REF! | H17: =B17 -> #REF! | I17: =C17 -> #REF! | J17: =D17 -> #REF! | K17: =E17 -> #REF!
A18: =#REF! -> #REF! | B18: =#REF! -> #REF! | C18: =#REF! -> #REF! | D18: =#REF! -> #REF! | E18: =#REF! -> #REF! | G18: =A18 -> #REF! | H18: =B18 -> #REF! | I18: =C18 -> #REF! | J18: =D18 -> #REF! | K18: =E18 -> #REF!
A19: =#REF! -> #REF! | B19: =#REF! -> #REF! | C19: =#REF! -> #REF! | D19: =#REF! -> #REF! | E19: =#REF! -> #REF! | G19: =A19 -> #REF! | H19: =B19 -> #REF! | I19: =C19 -> #REF! | J19: =D19 -> #REF! | K19: =E19 -> #REF!
A20: =#REF! -> #REF! | B20: =#REF! -> #REF! | C20: =#REF! -> #REF! | D20: =#REF! -> #REF! | E20: =#REF! -> #REF! | G20: =A20 -> #REF! | H20: =B20 -> #REF! | I20: =C20 -> #REF! | J20: =D20 -> #REF! | K20: =E20 -> #REF!
A21: =#REF! -> #REF! | B21: =#REF! -> #REF! | C21: =#REF! -> #REF! | D21: =#REF! -> #REF! | E21: =#REF! -> #REF! | G21: =A21 -> #REF! | H21: =B21 -> #REF! | I21: =C21 -> #REF! | J21: =D21 -> #REF! | K21: =E21 -> #REF!
A22: =#REF! -> #REF! | B22: =#REF! -> #REF! | C22: =#REF! -> #REF! | D22: =#REF! -> #REF! | E22: =#REF! -> #REF! | G22: =A22 -> #REF! | H22: =B22 -> #REF! | I22: =C22 -> #REF! | J22: =D22 -> #REF! | K22: =E22 -> #REF!
A23: =#REF! -> #REF! | B23: =#REF! -> #REF! | C23: =#REF! -> #REF! | D23: =#REF! -> #REF! | E23: =#REF! -> #REF! | G23: =A23 -> #REF! | H23: =B23 -> #REF! | I23: =C23 -> #REF! | J23: =D23 -> #REF! | K23: =E23 -> #REF!
A24: =#REF! -> #REF! | B24: =#REF! -> #REF! | C24: =#REF! -> #REF! | D24: =#REF! -> #REF! | E24: =#REF! -> #REF! | G24: =A24 -> #REF! | H24: =B24 -> #REF! | I24: =C24 -> #REF! | J24: =D24 -> #REF! | K24: =E24 -> #REF!
... A1842: =#REF! -> #REF! | B1842: =#REF! -> #REF! | C1842: =#REF! -> #REF! | D1842: =#REF! -> #REF! | E1842: =#REF! -> #REF! | G1842: =A1842 -> #REF! | H1842: =B1842 -> #REF! | I1842: =C1842 -> #REF! | J1842: =D1842 -> #REF! | K1842: =E1842 -> #REF!
G1843: =A1843 -> 0 | H1843: =B1843 -> 0 | I1843: =C1843 -> 0 | J1843: =D1843 -> 0 | K1843: =E1843 -> 0
G1844: =A1844 -> 0 | H1844: =B1844 -> 0 | I1844: =C1844 -> 0 | J1844: =D1844 -> 0 | K1844: =E1844 -> 0
G1845: =A1845 -> 0 | H1845: =B1845 -> 0 | I1845: =C1845 -> 0 | J1845: =D1845 -> 0 | K1845: =E1845 -> 0
G1846: =A1846 -> 0 | H1846: =B1846 -> 0 | I1846: =C1846 -> 0 | J1846: =D1846 -> 0 | K1846: =E1846 -> 0
G1847: =A1847 -> 0 | H1847: =B1847 -> 0 | I1847: =C1847 -> 0 | J1847: =D1847 -> 0 | K1847: =E1847 -> 0
G1848: =A1848 -> 0 | H1848: =B1848 -> 0 | I1848: =C1848 -> 0 | J1848: =D1848 -> 0 | K1848: =E1848 -> 0
G1849: =A1849 -> 0 | H1849: =B1849 -> 0 | I1849: =C1849 -> 0 | J1849: =D1849 -> 0 | K1849: =E1849 -> 0
G1850: =A1850 -> 0 | H1850: =B1850 -> 0 | I1850: =C1850 -> 0 | J1850: =D1850 -> 0 | K1850: =E1850 -> 0
G1851: =A1851 -> 0 | H1851: =B1851 -> 0 | I1851: =C1851 -> 0 | J1851: =D1851 -> 0 | K1851: =E1851 -> 0
G1852: =A1852 -> 0 | H1852: =B1852 -> 0 | I1852: =C1852 -> 0 | J1852: =D1852 -> 0 | K1852: =E1852 -> 0
G1853: =A1853 -> 0 | H1853: =B1853 -> 0 | I1853: =C1853 -> 0 | J1853: =D1853 -> 0 | K1853: =E1853 -> 0
G1854: =A1854 -> 0 | H1854: =B1854 -> 0 | I1854: =C1854 -> 0 | J1854: =D1854 -> 0 | K1854: =E1854 -> 0
... G4672: =A4672 -> 0 | H4672: =B4672 -> 0 | I4672: =C4672 -> 0 | J4672: =D4672 -> 0 | K4672: =E4672 -> 0

Sheet Sheet7
C3: Certero
C4: Muy probable
C5: Probable
C6: Alguna probabilidad
C7: Posible
C8: Improbable
C9: Altamente improbable
C10: Casi imposible
C11: Imposible | D11: =COUNTIFS((Matriz!K:K),0,(Matriz!I:I),0.1) -> 0 | E11: =COUNTIFS((Matriz!L:L),0,(Matriz!J:J),0.5) -> 0 | F11: =COUNTIFS((Matriz!M:M),0,(Matriz!K:K),1) -> 0 | G11: =COUNTIFS((Matriz!N:N),0,(Matriz!L:L),2) -> 0 | H11: =COUNTIFS((Matriz!O:O),0,(Matriz!M:M),4) -> 0 | I11: =COUNTIFS((Matriz!P:P),0,(Matriz!N:N),8) -> 0 | J11: =COUNTIFS((Matriz!Q:Q),0,(Matriz!O:O),15) -> 0
D12: Rasguño o raspadura | E12: Cortadura o efecto leve a la salud | F12: Fractura de hueso menor (dedos) o enfermedad ocupacional menor temporal | G12: Fractura de hueso mayor (brazo, pierna) o enfermedad ocupacional menor permanente | H12: Pérdida de un ojo, un dedo o enfermedad ocupacional seria temporal (LTA) | I12: Pérdida de los dos ojos, manos, piernas o enfermedad ocupacional seria permanente | J12: Muerte

Sheet Estandares Implementados
C2: Column Labels
C3: (blank) | D3: SI | E3: NO | F3: Grand Total
B4: Count of Implementado en Gemba | D4: 52 | E4: 50 | F4: 102

Sheet Peligros Identificados
A1: Row Labels | B1: Count of Peligros identificados
A2: (blank)
A3: Caída al mismo nivel | B3: 14
A4: Partes en movimiento | B4: 12
A5: Electricidad | B5: 13
A6: Amoniaco | B6: 13
A7: Piso resbaloso | B7: 13
A8: Filos | B8: 13
A9: Superficies calientes | B9: 9
A10: Engranes expuestos | B10: 1
A11: Grand Total | B11: 88

Sheet Grafica Área
A2: Row Labels | B2: Count of Área
A3: (blank)
A4: DESCONGELADO | B4: 1
A5: SALMUERAS | B5: 1
A6: INYECCIÓN | B6: 1
A7: FORMULACION | B7: 1
A8: MASAJEO | B8: 1
A9: EMBUTIDO | B9: 1
A10: COCIMIENTO Y ENFRIAMIENTO | B10: 1
A11: DESCARGA DE PRODUCTO | B11: 1
A12: EMPAQUE | B12: 1
A13: REBANADOS | B13: 1
A14: LAVADO DE CANASTILLAS | B14: 1
A15: LAVADO DE PILAS | B15: 1
... A41: Grand Total | B41: 37

Sheet Graficas Nivel Riesgo y Estatus
A3: Count of Nivel de riesgo (Actual) | B3: Column Labels
A4: Row Labels | B4: Bajo | C4: Insignificante | D4: Medio | E4: Muy Bajo | F4: #N/A | G4: (blank) | H4: Grand Total
A5: Atitalaquia | C5: 3 | D5: 2 | H5: 5
A6: Celaya | C6: 3 | E6: 1 | F6: 1 | H6: 5
A7: Chihuahua | C7: 2 | D7: 1 | E7: 2 | H7: 5
A8: Eugenia | C8: 5 | H8: 5
A9: Guadalajara | C9: 5 | F9: 1 | H9: 6
A10: Lagos de Moreno Quesos | B10: 1 | C10: 3 | E10: 1 | H10: 5
A11: Lagos de Moreno Yogurt | B11: 2 | C11: 2 | E11: 1 | H11: 5
A12: Linares | B12: 1 | C12: 2 | D12: 1 | E12: 1 | H12: 5
A13: Molino | C13: 3 | D13: 2 | H13: 5
A14: Noreste | C14: 2 | D14: 1 | E14: 2 | H14: 5
A15: Pénjamo | B15: 2 | C15: 2 | E15: 1 | H15: 5
A16: Pizzas | C16: 3 | E16: 2 | H16: 5
A17: Sabinas | C17: 2 | E17: 2 | F17: 1 | H17: 5
A18: Saltillo | B18: 1 | C18: 4 | H18: 5
A19: Supremo | C19: 2 | D19: 3 | H19: 5
A20: Tangamanga | B20: 2 | C20: 2 | D20: 1 | H20: 5
A21: Xalostoc | B21: 1 | C21: 4 | E21: 1 | F21: 1 | H21: 7
A22: (blank)
A23: Grand Total | B23: 10 | C23: 49 | D23: 11 | E23: 14 | F23: 4 | H23: 88
A32: Count of Estatus | B32: Column Labels
A33: Row Labels | B33: (blank) | C33: Abierto | D33: Cerrado | E33: Grand Total
A34: Atitalaquia | C34: 3 | D34: 2 | E34: 5
A35: Chihuahua | C35: 3 | D35: 2 | E35: 5
A36: Eugenia | C36: 2 | D36: 3 | E36: 5
A37: Guadalajara | C37: 3 | D37: 3 | E37: 6
A38: Linares | C38: 3 | D38: 2 | E38: 5
A39: Molino | C39: 2 | D39: 3 | E39: 5
A40: Noreste | C40: 2 | D40: 3 | E40: 5
A41: Sabinas | C41: 3 | D41: 2 | E41: 5
A42: Tangamanga | C42: 2 | D42: 3 | E42: 5
A43: Xalostoc | C43: 4 | D43: 3 | E43: 7
A44: (blank)
A45: Pizzas | C45: 2 | D45: 3 | E45: 5
A46: Supremo | C46: 3 | D46: 2 | E46: 5
A47: Saltillo | C47: 3 | D47: 2 | E47: 5
A48: Celaya | C48: 2 | D48: 3 | E48: 5
A49: Pénjamo | C49: 2 | D49: 3 | E49: 5
A50: Lagos de Moreno Quesos | C50: 3 | D50: 2 | E50: 5
...

Sheet 1.-Inventario para HRN
A1: FORMATO DE INVENTARIO DE PUESTO DE TRABAJO.
A2: Realizado por: _________________________ Validado por:___________________ Fecha: _________
A3: Puesto de trabajo involucrado: _________________ Línea o equipo:_______________________________________________
A4: No. | B4: Nombre del puesto | C4: Tipo de tarea | D4: ¿Que área realiza la tarea? | E4: Frecuencia de ejecución | F4: Observaciones

Sheet 2.-HRN
C1: FORMATO PARA REALIZAR EVALUACIONES DE RIESGOS DE UNA TAREA
C2: Nombre Lider: | H2: Puesto de trabajo: | AL2: Fecha de inicio de Elaboración:
B4: Descripción | K4: Contramedidas Existentes | M4: Riesgo Actual | W4: "Prioridad" | X4: Plan de acción | AD4: Contramedidas Adicionales | AF4: Riesgo disminuido | AP4: Estandar | AQ4: Marco Normativo
B5: Planta | C5: codigo | D5: Fecha | E5: Área | F5: Descripción de las tareas que componen el puesto | G5: Fotografía de la tarea | H5: Peligros identificados | I5: Mecanismo de lesión (Ligar tabla) | J5: Descripción del Riesgo (pasos+peligros+mecanismos de lesión) | K5: Controles (A) | L5: Defensas (A) | M5: Frecuencia de Exposición (Actual) | N5: Valor FEA | O5: Número de Personas (Actual) | P5: Valor NPA | Q5: Gravedad (Actual) | R5: Valor GA | S5: Probabilidad (Actual) | T5: Valor PA | U5: HRN (Actual) | V5: Nivel de riesgo (Actual) | W5: Tiempo de acción | X5: Plan de acción (¿Qué y el cómo?) | Y5: Fecha programada | Z5: Estatus | AA5: Piramide de Contramedidas | AB5: Responsable | AC5: Fecha cierre | AD5: Controles (N) | AE5: Defensas (N) | AF5: Frecuencia de Exposición (Nuevas) | AG5: Valor FEN | AH5: Número de Personas (Nuevas) | AI5: Valor NPN | AJ5: Gravedad (Nuevas) | AK5: Valor GN | AL5: Probabilidad (Nuevas) | AM5: Valor PN | AN5: HRN (Nuevas) | AO5: Nivel de riesgo (Nuevas) | AP5: Implementado en Gemba | AQ5: Normativa
B6: Sabinas | C6: MADUROS-IT-P-QM-11-01 | D6: 45584 | E6: Materia prima | F6: 1.-Manipulación de insumos | H6: Polvos suspendidos | I6: 10.- Escapes al ambiente de: Amoniaco, Gas, Sustancias Peligrosas. | J6: Al estar pesando y manipulando, polvos de concentrado de chile, existe el riesgo de irritación en los ojos, naris o con la piel. | K6: 1.-Capacitacion en Politica de Seguridad 2.-Capcitacion de Reglas de Seguridad Generales 3.-Realizacion de Calentamiento y/o gimnasia laoboral 4.-Capacitación en procedimiento IT-P-QM-11 Producción navideño 3 chiles | L6: 1.-Uso de calzado de seguridad 2.-Uso de guante para químico 3.-Uso de mascarilla de protección respiratoria 4.-Uso de googles de seguridad 5.-Uso de mandil | M6: Anual | N6: =VLOOKUP(M6,Tablas!$A$31:$B$38,2,FALSE) -> 0.2 | O6: 1-2 personas | P6: =VLOOKUP(O6,Tablas!$A$41:$B$47,2,FALSE) -> 1 | Q6: Cortadura o efecto leve a la salud | R6: =VLOOKUP(Q6,Tablas!$A$51:$B$59,2,FALSE) -> 0.5 | S6: Posible | T6: =VLOOKUP(S6,Tablas!$A$62:$B$72,2,FALSE) -> 2 | U6: =N6*P6*R6*T6 -> 0.2 | V6: {=_xlfn.IFS(U6<=1,Tablas!$A$75,U6<=5,Tablas!$A$76,U6<=10,Tablas!$A$77,U6<=50,Tablas!$A$78,U6<=100,Tablas!$A$79,U6<=500,Tablas!$A$80,U6<=999,Tablas!$A$81,U6>1000,Tablas!A82)} -> Insignificante | W6: {=_xlfn.IFS(V6=Tablas!$A$87,Tablas!$B$87,V6=Tablas!$A$88,Tablas!$B$88,V6=Tablas!$A$89,Tablas!$B$89,V6=Tablas!$A$90,Tablas!$B$90,V6=Tablas!$A$91,Tablas!$B$91,V6=Tablas!$A$92,Tablas!$B$92,V6=Tablas!$A$93,Tablas!$B$93,V6=Tablas!$A$94,Tablas!$B$94)} -> Mayor a un año | Z6: Cerrado | AF6: Anual | AG6: =VLOOKUP(AF6,Tablas!A31:B38,2,FALSE) -> 0.2 | AH6: >50 personas | AI6: =VLOOKUP(AH6,Tablas!A41:B47,2,FALSE) -> 12 | AJ6: Fractura de hueso menor (dedos) o enfermedad ocupacional menor temporal | AK6: =VLOOKUP(AJ6,Tablas!A51:B59,2,FALSE) -> 1 | AL6: Imposible | AM6: =VLOOKUP(AL6,Tablas!A62:B72,2,FALSE) -> 0 | AN6: =AG6*AI6*AK6*AM6 -> 0 | AO6: {=_xlfn.IFS(AN6<=1,Tablas!$A$75,AN6<=5,Tablas!$A$76,AN6<=10,Tablas!$A$77,AN6<=50,Tablas!$A$78,AN6<=100,Tablas!$A$79,AN6<=500,Tablas!$A$80,AN6<=999,Tablas!$A$81,AN6>1000,Tablas!T82)} -> Insignificante | AP6: SI
B7: Sabinas | C7: MADUROS-IT-P-QM-11-02 | D7: 45584 | E7: Maduros | F7: 1.-Manipulación de isnumos 2.-Operación de prensa 3.-Manejo manual de cargas. | H7: Movimientos inesperados | I7: 3.- Atrapado entre o bajo (aplastados o amputados) | J7: Riesgo pormanejo manual de cargas, Riesgo al manipular moldes con queso,al introducir y retirar moldes de presna. | K7: 1.-Capacitacion en Politica de Seguridad 2.-Capcitacion de Reglas de Seguridad Generales 3.-Realizacion de Calentamiento y/o gimnasia laoboral 4.-Capacitación en procedimiento IT-P-QM-11 Producción navideño 3 chiles. 5.-Señalización de riesgos 6.-Señalizacion de Tuberias 7.-Controles visulaes de los controles del equipo 8.-Piso o tapete antiderrapante 9.-Dispositivos de control de presión de aire comprimido 10.-instalacion dispositivos de corte de energia adecuados para aplcar LOTO | L7: Paros de emergencia Uso de guante para químico Uso de bota de PVC sanitaria Brigadas de emergencia Vigilancia Medica | M7: Diario | N7: =VLOOKUP(M7,Tablas!$A$31:$B$38,2,FALSE) -> 2.5 | O7: 3-7 personas | P7: =VLOOKUP(O7,Tablas!$A$41:$B$47,2,FALSE) -> 2 | Q7: Fractura de hueso menor (dedos) o enfermedad ocupacional menor temporal | R7: =VLOOKUP(Q7,Tablas!$A$51:$B$59,2,FALSE) -> 1 | S7: Posible | T7: =VLOOKUP(S7,Tablas!$A$62:$B$72,2,FALSE) -> 2 | U7: =N7*P7*R7*T7 -> 10 | V7: {=_xlfn.IFS(U7<=1,Tablas!$A$75,U7<=5,Tablas!$A$76,U7<=10,Tablas!$A$77,U7<=50,Tablas!$A$78,U7<=100,Tablas!$A$79,U7<=500,Tablas!$A$80,U7<=999,Tablas!$A$81,U7>1000,Tablas!A83)} -> Bajo | W7: {=_xlfn.IFS(V7=Tablas!$A$87,Tablas!$B$87,V7=Tablas!$A$88,Tablas!$B$88,V7=Tablas!$A$89,Tablas!$B$89,V7=Tablas!$A$90,Tablas!$B$90,V7=Tablas!$A$91,Tablas!$B$91,V7=Tablas!$A$92,Tablas!$B$92,V7=Tablas!$A$93,Tablas!$B$93,V7=Tablas!$A$94,Tablas!$B$94)} -> Menor a tres meses | AF7: Infrecuente | AG7: =VLOOKUP(AF7,Tablas!A32:B39,2,FALSE) -> 0.1 | AH7: 1-2 personas | AI7: =VLOOKUP(AH7,Tablas!A42:B48,2,FALSE) -> 1 | AJ7: Rasguño o raspadura | AK7: =VLOOKUP(AJ7,Tablas!A52:B60,2,FALSE) -> 0.1 | AL7: Imposible | AM7: =VLOOKUP(AL7,Tablas!A63:B73,2,FALSE) -> 0 | AN7: =AG7*AI7*AK7*AM7 -> 0 | AO7: {=_xlfn.IFS(AN7<=1,Tablas!$A$75,AN7<=5,Tablas!$A$76,AN7<=10,Tablas!$A$77,AN7<=50,Tablas!$A$78,AN7<=100,Tablas!$A$79,AN7<=500,Tablas!$A$80,AN7<=999,Tablas!$A$81,AN7>1000,Tablas!T83)} -> Insignificante
B8: Sabinas | C8: MADUROS-IT-P-QM-11-03 | D8: 45585 | E8: Maduros | F8: 1.-Manipulación de isnumos 2.-Operación de prensa 3.-Manejo manual de cargas. | H8: Superficie de trabajo | I8: 7.- Caída del mismo nivel | J8: Riesgo pormanejo manual de cargas, Riesgo al de resbalon al manipular el molde. | K8: 1.-Capacitacion en Politica de Seguridad 2.-Capcitacion de Reglas de Seguridad Generales 3.-Realizacion de Calentamiento y/o gimnasia laoboral 4.-Capacitación en procedimiento IT-P-QM-11 Producción navideño 3 chiles | L8: Paros de emergencia Uso de guante para químico Uso de bota de PVC sanitaria Brigadas de emergencia Vigilancia Medica | M8: Diario | N8: =VLOOKUP(M8,Tablas!$A$31:$B$38,2,FALSE) -> 2.5 | O8: 3-7 personas | P8: =VLOOKUP(O8,Tablas!$A$41:$B$47,2,FALSE) -> 2 | Q8: Fractura de hueso menor (dedos) o enfermedad ocupacional menor temporal | R8: =VLOOKUP(Q8,Tablas!$A$51:$B$59,2,FALSE) -> 1 | S8: Posible | T8: =VLOOKUP(S8,Tablas!$A$62:$B$72,2,FALSE) -> 2 | U8: =N8*P8*R8*T8 -> 10 | V8: {=_xlfn.IFS(U8<=1,Tablas!$A$75,U8<=5,Tablas!$A$76,U8<=10,Tablas!$A$77,U8<=50,Tablas!$A$78,U8<=100,Tablas!$A$79,U8<=500,Tablas!$A$80,U8<=999,Tablas!$A$81,U8>1000,Tablas!A84)} -> Bajo | W8: {=_xlfn.IFS(V8=Tablas!$A$87,Tablas!$B$87,V8=Tablas!$A$88,Tablas!$B$88,V8=Tablas!$A$89,Tablas!$B$89,V8=Tablas!$A$90,Tablas!$B$90,V8=Tablas!$A$91,Tablas!$B$91,V8=Tablas!$A$92,Tablas!$B$92,V8=Tablas!$A$93,Tablas!$B$93,V8=Tablas!$A$94,Tablas!$B$94)} -> Menor a tres meses | AF8: Anual | AG8: =VLOOKUP(AF8,Tablas!A33:B40,2,FALSE) -> 0.2 | AH8: 3-7 personas | AI8: =VLOOKUP(AH8,Tablas!A43:B49,2,FALSE) -> 2 | AJ8: Fractura de hueso menor (dedos) o enfermedad ocupacional menor temporal | AK8: =VLOOKUP(AJ8,Tablas!A53:B61,2,FALSE) -> 1 | AL8: Muy probable | AM8: =VLOOKUP(AL8,Tablas!A64:B74,2,FALSE) -> 10 | AN8: =AG8*AI8*AK8*AM8 -> 4 | AO8: {=_xlfn.IFS(AN8<=1,Tablas!$A$75,AN8<=5,Tablas!$A$76,AN8<=10,Tablas!$A$77,AN8<=50,Tablas!$A$78,AN8<=100,Tablas!$A$79,AN8<=500,Tablas!$A$80,AN8<=999,Tablas!$A$81,AN8>1000,Tablas!T84)} -> Muy Bajo
B9: Sabinas | C9: MADUROS-IT-P-QM-11-04 | D9: 45586 | E9: Maduros | F9: 1.-Manipulación de isnumos 2.-Operación de prensa 3.-Manejo manual de cargas. 4.- Manejo de quimicos. | H9: Golpearse con o contra objetos | I9: 1.- Golpeado Contra (chocar contra) | J9: Al momento de realizar limpieza, estisten riesgos por manipulación de quimico, caidas a mismo nivel | K9: 1.-Capacitacion en Politica de Seguridad 2.-Capcitacion de Reglas de Seguridad Generales 3.-Realizacion de Calentamiento y/o gimnasia laoboral 4.-Capacitación en procedimiento IT-P-QM-11 Producción navideño 3 chiles | L9: Paros de emergencia Uso de guante para químico Uso de bota de PVC sanitaria Brigadas de emergencia Vigilancia Medica | M9: Diario | N9: =VLOOKUP(M9,Tablas!$A$31:$B$38,2,FALSE) -> 2.5 | O9: 1-2 personas | P9: =VLOOKUP(O9,Tablas!$A$41:$B$47,2,FALSE) -> 1 | Q9: Fractura de hueso menor (dedos) o enfermedad ocupacional menor temporal | R9: =VLOOKUP(Q9,Tablas!$A$51:$B$59,2,FALSE) -> 1 | S9: Posible | T9: =VLOOKUP(S9,Tablas!$A$62:$B$72,2,FALSE) -> 2 | U9: =N9*P9*R9*T9 -> 5 | V9: {=_xlfn.IFS(U9<=1,Tablas!$A$75,U9<=5,Tablas!$A$76,U9<=10,Tablas!$A$77,U9<=50,Tablas!$A$78,U9<=100,Tablas!$A$79,U9<=500,Tablas!$A$80,U9<=999,Tablas!$A$81,U9>1000,Tablas!A85)} -> Muy Bajo | W9: {=_xlfn.IFS(V9=Tablas!$A$87,Tablas!$B$87,V9=Tablas!$A$88,Tablas!$B$88,V9=Tablas!$A$89,Tablas!$B$89,V9=Tablas!$A$90,Tablas!$B$90,V9=Tablas!$A$91,Tablas!$B$91,V9=Tablas!$A$92,Tablas!$B$92,V9=Tablas!$A$93,Tablas!$B$93,V9=Tablas!$A$94,Tablas!$B$94)} -> Menor a un año | AG9: =VLOOKUP(AF9,Tablas!A34:B41,2,FALSE) -> #N/A | AI9: =VLOOKUP(AH9,Tablas!A44:B50,2,FALSE) -> #N/A | AK9: =VLOOKUP(AJ9,Tablas!A54:B62,2,FALSE) -> #N/A | AM9: =VLOOKUP(AL9,Tablas!A65:B75,2,FALSE) -> #N/A | AN9: =AG9*AI9*AK9*AM9 -> #N/A | AO9: {=_xlfn.IFS(AN9<=1,Tablas!$A$75,AN9<=5,Tablas!$A$76,AN9<=10,Tablas!$A$77,AN9<=50,Tablas!$A$78,AN9<=100,Tablas!$A$79,AN9<=500,Tablas!$A$80,AN9<=999,Tablas!$A$81,AN9>1000,Tablas!T85)} -> #N/A
N10: =VLOOKUP(M10,Tablas!$A$31:$B$38,2,FALSE) -> #N/A | P10: =VLOOKUP(O10,Tablas!$A$41:$B$47,2,FALSE) -> #N/A | R10: =VLOOKUP(Q10,Tablas!$A$51:$B$59,2,FALSE) -> #N/A | T10: =VLOOKUP(S10,Tablas!$A$62:$B$72,2,FALSE) -> #N/A | U10: =N10*P10*R10*T10 -> #N/A | V10: {=_xlfn.IFS(U10<=1,Tablas!$A$75,U10<=5,Tablas!$A$76,U10<=10,Tablas!$A$77,U10<=50,Tablas!$A$78,U10<=100,Tablas!$A$79,U10<=500,Tablas!$A$80,U10<=999,Tablas!$A$81,U10>1000,Tablas!A92)} -> #N/A | W10: {=_xlfn.IFS(V10=Tablas!$A$87,Tablas!$B$87,V10=Tablas!$A$88,Tablas!$B$88,V10=Tablas!$A$89,Tablas!$B$89,V10=Tablas!$A$90,Tablas!$B$90,V10=Tablas!$A$91,Tablas!$B$91,V10=Tablas!$A$92,Tablas!$B$92,V10=Tablas!$A$93,Tablas!$B$93,V10=Tablas!$A$94,Tablas!$B$94)} -> #N/A | AG10: =VLOOKUP(AF10,Tablas!A41:B48,2,FALSE) -> #N/A | AI10: =VLOOKUP(AH10,Tablas!A51:B57,2,FALSE) -> #N/A | AK10: =VLOOKUP(AJ10,Tablas!A61:B69,2,FALSE) -> #N/A | AM10: =VLOOKUP(AL10,Tablas!A72:B82,2,FALSE) -> #N/A | AN10: =AG10*AI10*AK10*AM10 -> #N/A | AO10: {=_xlfn.IFS(AN10<=1,Tablas!$A$75,AN10<=5,Tablas!$A$76,AN10<=10,Tablas!$A$77,AN10<=50,Tablas!$A$78,AN10<=100,Tablas!$A$79,AN10<=500,Tablas!$A$80,AN10<=999,Tablas!$A$81,AN10>1000,Tablas!T92)} -> #N/A
N11: =VLOOKUP(M11,Tablas!$A$31:$B$38,2,FALSE) -> #N/A | P11: =VLOOKUP(O11,Tablas!$A$41:$B$47,2,FALSE) -> #N/A | R11: =VLOOKUP(Q11,Tablas!$A$51:$B$59,2,FALSE) -> #N/A | T11: =VLOOKUP(S11,Tablas!$A$62:$B$72,2,FALSE) -> #N/A | U11: =N11*P11*R11*T11 -> #N/A | V11: {=_xlfn.IFS(U11<=1,Tablas!$A$75,U11<=5,Tablas!$A$76,U11<=10,Tablas!$A$77,U11<=50,Tablas!$A$78,U11<=100,Tablas!$A$79,U11<=500,Tablas!$A$80,U11<=999,Tablas!$A$81,U11>1000,Tablas!A93)} -> #N/A | W11: {=_xlfn.IFS(V11=Tablas!$A$87,Tablas!$B$87,V11=Tablas!$A$88,Tablas!$B$88,V11=Tablas!$A$89,Tablas!$B$89,V11=Tablas!$A$90,Tablas!$B$90,V11=Tablas!$A$91,Tablas!$B$91,V11=Tablas!$A$92,Tablas!$B$92,V11=Tablas!$A$93,Tablas!$B$93,V11=Tablas!$A$94,Tablas!$B$94)} -> #N/A | AG11: =VLOOKUP(AF11,Tablas!A42:B49,2,FALSE) -> #N/A | AI11: =VLOOKUP(AH11,Tablas!A52:B58,2,FALSE) -> #N/A | AK11: =VLOOKUP(AJ11,Tablas!A62:B70,2,FALSE) -> #N/A | AM11: =VLOOKUP(AL11,Tablas!A73:B83,2,FALSE) -> #N/A | AN11: =AG11*AI11*AK11*AM11 -> #N/A | AO11: {=_xlfn.IFS(AN11<=1,Tablas!$A$75,AN11<=5,Tablas!$A$76,AN11<=10,Tablas!$A$77,AN11<=50,Tablas!$A$78,AN11<=100,Tablas!$A$79,AN11<=500,Tablas!$A$80,AN11<=999,Tablas!$A$81,AN11>1000,Tablas!T93)} -> #N/A
N12: =VLOOKUP(M12,Tablas!$A$31:$B$38,2,FALSE) -> #N/A | P12: =VLOOKUP(O12,Tablas!$A$41:$B$47,2,FALSE) -> #N/A | R12: =VLOOKUP(Q12,Tablas!$A$51:$B$59,2,FALSE) -> #N/A | T12: =VLOOKUP(S12,Tablas!$A$62:$B$72,2,FALSE) -> #N/A | U12: =N12*P12*R12*T12 -> #N/A | V12: {=_xlfn.IFS(U12<=1,Tablas!$A$75,U12<=5,Tablas!$A$76,U12<=10,Tablas!$A$77,U12<=50,Tablas!$A$78,U12<=100,Tablas!$A$79,U12<=500,Tablas!$A$80,U12<=999,Tablas!$A$81,U12>1000,Tablas!A94)} -> #N/A | W12: {=_xlfn.IFS(V12=Tablas!$A$87,Tablas!$B$87,V12=Tablas!$A$88,Tablas!$B$88,V12=Tablas!$A$89,Tablas!$B$89,V12=Tablas!$A$90,Tablas!$B$90,V12=Tablas!$A$91,Tablas!$B$91,V12=Tablas!$A$92,Tablas!$B$92,V12=Tablas!$A$93,Tablas!$B$93,V12=Tablas!$A$94,Tablas!$B$94)} -> #N/A | AG12: =VLOOKUP(AF12,Tablas!A43:B50,2,FALSE) -> #N/A | AI12: =VLOOKUP(AH12,Tablas!A53:B59,2,FALSE) -> #N/A | AK12: =VLOOKUP(AJ12,Tablas!A63:B71,2,FALSE) -> #N/A | AM12: =VLOOKUP(AL12,Tablas!A74:B84,2,FALSE) -> #N/A | AN12: =AG12*AI12*AK12*AM12 -> #N/A | AO12: {=_xlfn.IFS(AN12<=1,Tablas!$A$75,AN12<=5,Tablas!$A$76,AN12<=10,Tablas!$A$77,AN12<=50,Tablas!$A$78,AN12<=100,Tablas!$A$79,AN12<=500,Tablas!$A$80,AN12<=999,Tablas!$A$81,AN12>1000,Tablas!T94)} -> #N/A
N13: =VLOOKUP(M13,Tablas!$A$31:$B$38,2,FALSE) -> #N/A | P13: =VLOOKUP(O13,Tablas!$A$41:$B$47,2,FALSE) -> #N/A | R13: =VLOOKUP(Q13,Tablas!$A$51:$B$59,2,FALSE) -> #N/A | T13: =VLOOKUP(S13,Tablas!$A$62:$B$72,2,FALSE) -> #N/A | U13: =N13*P13*R13*T13 -> #N/A | V13: {=_xlfn.IFS(U13<=1,Tablas!$A$75,U13<=5,Tablas!$A$76,U13<=10,Tablas!$A$77,U13<=50,Tablas!$A$78,U13<=100,Tablas!$A$79,U13<=500,Tablas!$A$80,U13<=999,Tablas!$A$81,U13>1000,Tablas!A95)} -> #N/A | W13: {=_xlfn.IFS(V13=Tablas!$A$87,Tablas!$B$87,V13=Tablas!$A$88,Tablas!$B$88,V13=Tablas!$A$89,Tablas!$B$89,V13=Tablas!$A$90,Tablas!$B$90,V13=Tablas!$A$91,Tablas!$B$91,V13=Tablas!$A$92,Tablas!$B$92,V13=Tablas!$A$93,Tablas!$B$93,V13=Tablas!$A$94,Tablas!$B$94)} -> #N/A | AG13: =VLOOKUP(AF13,Tablas!A44:B51,2,FALSE) -> #N/A | AI13: =VLOOKUP(AH13,Tablas!A54:B60,2,FALSE) -> #N/A | AK13: =VLOOKUP(AJ13,Tablas!A64:B72,2,FALSE) -> #N/A | AM13: =VLOOKUP(AL13,Tablas!A75:B85,2,FALSE) -> #N/A | AN13: =AG13*AI13*AK13*AM13 -> #N/A | AO13: {=_xlfn.IFS(AN13<=1,Tablas!$A$75,AN13<=5,Tablas!$A$76,AN13<=10,Tablas!$A$77,AN13<=50,Tablas!$A$78,AN13<=100,Tablas!$A$79,AN13<=500,Tablas!$A$80,AN13<=999,Tablas!$A$81,AN13>1000,Tablas!T95)} -> #N/A
N14: =VLOOKUP(M14,Tablas!$A$31:$B$38,2,FALSE) -> #N/A | P14: =VLOOKUP(O14,Tablas!$A$41:$B$47,2,FALSE) -> #N/A | R14: =VLOOKUP(Q14,Tablas!$A$51:$B$59,2,FALSE) -> #N/A | T14: =VLOOKUP(S14,Tablas!$A$62:$B$72,2,FALSE) -> #N/A | U14: =N14*P14*R14*T14 -> #N/A | V14: {=_xlfn.IFS(U14<=1,Tablas!$A$75,U14<=5,Tablas!$A$76,U14<=10,Tablas!$A$77,U14<=50,Tablas!$A$78,U14<=100,Tablas!$A$79,U14<=500,Tablas!$A$80,U14<=999,Tablas!$A$81,U14>1000,Tablas!A96)} -> #N/A | W14: {=_xlfn.IFS(V14=Tablas!$A$87,Tablas!$B$87,V14=Tablas!$A$88,Tablas!$B$88,V14=Tablas!$A$89,Tablas!$B$89,V14=Tablas!$A$90,Tablas!$B$90,V14=Tablas!$A$91,Tablas!$B$91,V14=Tablas!$A$92,Tablas!$B$92,V14=Tablas!$A$93,Tablas!$B$93,V14=Tablas!$A$94,Tablas!$B$94)} -> #N/A | AG14: =VLOOKUP(AF14,Tablas!A45:B52,2,FALSE) -> #N/A | AI14: =VLOOKUP(AH14,Tablas!A55:B61,2,FALSE) -> #N/A | AK14: =VLOOKUP(AJ14,Tablas!A65:B73,2,FALSE) -> #N/A | AM14: =VLOOKUP(AL14,Tablas!A76:B86,2,FALSE) -> #N/A | AN14: =AG14*AI14*AK14*AM14 -> #N/A | AO14: {=_xlfn.IFS(AN14<=1,Tablas!$A$75,AN14<=5,Tablas!$A$76,AN14<=10,Tablas!$A$77,AN14<=50,Tablas!$A$78,AN14<=100,Tablas!$A$79,AN14<=500,Tablas!$A$80,AN14<=999,Tablas!$A$81,AN14>1000,Tablas!T96)} -> #N/A
N15: =VLOOKUP(M15,Tablas!$A$31:$B$38,2,FALSE) -> #N/A | P15: =VLOOKUP(O15,Tablas!$A$41:$B$47,2,FALSE) -> #N/A | R15: =VLOOKUP(Q15,Tablas!$A$51:$B$59,2,FALSE) -> #N/A | T15: =VLOOKUP(S15,Tablas!$A$62:$B$72,2,FALSE) -> #N/A | U15: =N15*P15*R15*T15 -> #N/A | V15: {=_xlfn.IFS(U15<=1,Tablas!$A$75,U15<=5,Tablas!$A$76,U15<=10,Tablas!$A$77,U15<=50,Tablas!$A$78,U15<=100,Tablas!$A$79,U15<=500,Tablas!$A$80,U15<=999,Tablas!$A$81,U15>1000,Tablas!A97)} -> #N/A | W15: {=_xlfn.IFS(V15=Tablas!$A$87,Tablas!$B$87,V15=Tablas!$A$88,Tablas!$B$88,V15=Tablas!$A$89,Tablas!$B$89,V15=Tablas!$A$90,Tablas!$B$90,V15=Tablas!$A$91,Tablas!$B$91,V15=Tablas!$A$92,Tablas!$B$92,V15=Tablas!$A$93,Tablas!$B$93,V15=Tablas!$A$94,Tablas!$B$94)} -> #N/A | AG15: =VLOOKUP(AF15,Tablas!A46:B53,2,FALSE) -> #N/A | AI15: =VLOOKUP(AH15,Tablas!A56:B62,2,FALSE) -> #N/A | AK15: =VLOOKUP(AJ15,Tablas!A66:B74,2,FALSE) -> #N/A | AM15: =VLOOKUP(AL15,Tablas!A77:B87,2,FALSE) -> #N/A | AN15: =AG15*AI15*AK15*AM15 -> #N/A | AO15: {=_xlfn.IFS(AN15<=1,Tablas!$A$75,AN15<=5,Tablas!$A$76,AN15<=10,Tablas!$A$77,AN15<=50,Tablas!$A$78,AN15<=100,Tablas!$A$79,AN15<=500,Tablas!$A$80,AN15<=999,Tablas!$A$81,AN15>1000,Tablas!T97)} -> #N/A
N16: =VLOOKUP(M16,Tablas!$A$31:$B$38,2,FALSE) -> #N/A | P16: =VLOOKUP(O16,Tablas!$A$41:$B$47,2,FALSE) -> #N/A | R16: =VLOOKUP(Q16,Tablas!$A$51:$B$59,2,FALSE) -> #N/A | T16: =VLOOKUP(S16,Tablas!$A$62:$B$72,2,FALSE) -> #N/A | U16: =N16*P16*R16*T16 -> #N/A | V16: {=_xlfn.IFS(U16<=1,Tablas!$A$75,U16<=5,Tablas!$A$76,U16<=10,Tablas!$A$77,U16<=50,Tablas!$A$78,U16<=100,Tablas!$A$79,U16<=500,Tablas!$A$80,U16<=999,Tablas!$A$81,U16>1000,Tablas!A98)} -> #N/A | W16: {=_xlfn.IFS(V16=Tablas!$A$87,Tablas!$B$87,V16=Tablas!$A$88,Tablas!$B$88,V16=Tablas!$A$89,Tablas!$B$89,V16=Tablas!$A$90,Tablas!$B$90,V16=Tablas!$A$91,Tablas!$B$91,V16=Tablas!$A$92,Tablas!$B$92,V16=Tablas!$A$93,Tablas!$B$93,V16=Tablas!$A$94,Tablas!$B$94)} -> #N/A | AG16: =VLOOKUP(AF16,Tablas!A47:B54,2,FALSE) -> #N/A | AI16: =VLOOKUP(AH16,Tablas!A57:B63,2,FALSE) -> #N/A | AK16: =VLOOKUP(AJ16,Tablas!A67:B75,2,FALSE) -> #N/A | AM16: =VLOOKUP(AL16,Tablas!A78:B88,2,FALSE) -> #N/A | AN16: =AG16*AI16*AK16*AM16 -> #N/A | AO16: {=_xlfn.IFS(AN16<=1,Tablas!$A$75,AN16<=5,Tablas!$A$76,AN16<=10,Tablas!$A$77,AN16<=50,Tablas!$A$78,AN16<=100,Tablas!$A$79,AN16<=500,Tablas!$A$80,AN16<=999,Tablas!$A$81,AN16>1000,Tablas!T98)} -> #N/A
N17: =VLOOKUP(M17,Tablas!$A$31:$B$38,2,FALSE) -> #N/A | P17: =VLOOKUP(O17,Tablas!$A$41:$B$47,2,FALSE) -> #N/A | R17: =VLOOKUP(Q17,Tablas!$A$51:$B$59,2,FALSE) -> #N/A | T17: =VLOOKUP(S17,Tablas!$A$62:$B$72,2,FALSE) -> #N/A | U17: =N17*P17*R17*T17 -> #N/A | V17: {=_xlfn.IFS(U17<=1,Tablas!$A$75,U17<=5,Tablas!$A$76,U17<=10,Tablas!$A$77,U17<=50,Tablas!$A$78,U17<=100,Tablas!$A$79,U17<=500,Tablas!$A$80,U17<=999,Tablas!$A$81,U17>1000,Tablas!A99)} -> #N/A | W17: {=_xlfn.IFS(V17=Tablas!$A$87,Tablas!$B$87,V17=Tablas!$A$88,Tablas!$B$88,V17=Tablas!$A$89,Tablas!$B$89,V17=Tablas!$A$90,Tablas!$B$90,V17=Tablas!$A$91,Tablas!$B$91,V17=Tablas!$A$92,Tablas!$B$92,V17=Tablas!$A$93,Tablas!$B$93,V17=Tablas!$A$94,Tablas!$B$94)} -> #N/A | AG17: =VLOOKUP(AF17,Tablas!A48:B55,2,FALSE) -> #N/A | AI17: =VLOOKUP(AH17,Tablas!A58:B64,2,FALSE) -> #N/A | AK17: =VLOOKUP(AJ17,Tablas!A68:B76,2,FALSE) -> #N/A | AM17: =VLOOKUP(AL17,Tablas!A79:B89,2,FALSE) -> #N/A | AN17: =AG17*AI17*AK17*AM17 -> #N/A | AO17: {=_xlfn.IFS(AN17<=1,Tablas!$A$75,AN17<=5,Tablas!$A$76,AN17<=10,Tablas!$A$77,AN17<=50,Tablas!$A$78,AN17<=100,Tablas!$A$79,AN17<=500,Tablas!$A$80,AN17<=999,Tablas!$A$81,AN17>1000,Tablas!T99)} -> #N/A
N18: =VLOOKUP(M18,Tablas!$A$31:$B$38,2,FALSE) -> #N/A | P18: =VLOOKUP(O18,Tablas!$A$41:$B$47,2,FALSE) -> #N/A | R18: =VLOOKUP(Q18,Tablas!$A$51:$B$59,2,FALSE) -> #N/A | T18: =VLOOKUP(S18,Tablas!$A$62:$B$72,2,FALSE) -> #N/A | U18: =N18*P18*R18*T18 -> #N/A | V18: {=_xlfn.IFS(U18<=1,Tablas!$A$75,U18<=5,Tablas!$A$76,U18<=10,Tablas!$A$77,U18<=50,Tablas!$A$78,U18<=100,Tablas!$A$79,U18<=500,Tablas!$A$80,U18<=999,Tablas!$A$81,U18>1000,Tablas!A100)} -> #N/A | W18: {=_xlfn.IFS(V18=Tablas!$A$87,Tablas!$B$87,V18=Tablas!$A$88,Tablas!$B$88,V18=Tablas!$A$89,Tablas!$B$89,V18=Tablas!$A$90,Tablas!$B$90,V18=Tablas!$A$91,Tablas!$B$91,V18=Tablas!$A$92,Tablas!$B$92,V18=Tablas!$A$93,Tablas!$B$93,V18=Tablas!$A$94,Tablas!$B$94)} -> #N/A | AG18: =VLOOKUP(AF18,Tablas!A49:B56,2,FALSE) -> #N/A | AI18: =VLOOKUP(AH18,Tablas!A59:B65,2,FALSE) -> #N/A | AK18: =VLOOKUP(AJ18,Tablas!A69:B77,2,FALSE) -> #N/A | AM18: =VLOOKUP(AL18,Tablas!A80:B90,2,FALSE) -> #N/A | AN18: =AG18*AI18*AK18*AM18 -> #N/A | AO18: {=_xlfn.IFS(AN18<=1,Tablas!$A$75,AN18<=5,Tablas!$A$76,AN18<=10,Tablas!$A$77,AN18<=50,Tablas!$A$78,AN18<=100,Tablas!$A$79,AN18<=500,Tablas!$A$80,AN18<=999,Tablas!$A$81,AN18>1000,Tablas!T100)} -> #N/A
N19: =VLOOKUP(M19,Tablas!$A$31:$B$38,2,FALSE) -> #N/A | P19: =VLOOKUP(O19,Tablas!$A$41:$B$47,2,FALSE) -> #N/A | R19: =VLOOKUP(Q19,Tablas!$A$51:$B$59,2,FALSE) -> #N/A | T19: =VLOOKUP(S19,Tablas!$A$62:$B$72,2,FALSE) -> #N/A | U19: =N19*P19*R19*T19 -> #N/A | V19: {=_xlfn.IFS(U19<=1,Tablas!$A$75,U19<=5,Tablas!$A$76,U19<=10,Tablas!$A$77,U19<=50,Tablas!$A$78,U19<=100,Tablas!$A$79,U19<=500,Tablas!$A$80,U19<=999,Tablas!$A$81,U19>1000,Tablas!A101)} -> #N/A | W19: {=_xlfn.IFS(V19=Tablas!$A$87,Tablas!$B$87,V19=Tablas!$A$88,Tablas!$B$88,V19=Tablas!$A$89,Tablas!$B$89,V19=Tablas!$A$90,Tablas!$B$90,V19=Tablas!$A$91,Tablas!$B$91,V19=Tablas!$A$92,Tablas!$B$92,V19=Tablas!$A$93,Tablas!$B$93,V19=Tablas!$A$94,Tablas!$B$94)} -> #N/A | AG19: =VLOOKUP(AF19,Tablas!A50:B57,2,FALSE) -> #N/A | AI19: =VLOOKUP(AH19,Tablas!A60:B66,2,FALSE) -> #N/A | AK19: =VLOOKUP(AJ19,Tablas!A70:B78,2,FALSE) -> #N/A | AM19: =VLOOKUP(AL19,Tablas!A81:B91,2,FALSE) -> #N/A | AN19: =AG19*AI19*AK19*AM19 -> #N/A | AO19: {=_xlfn.IFS(AN19<=1,Tablas!$A$75,AN19<=5,Tablas!$A$76,AN19<=10,Tablas!$A$77,AN19<=50,Tablas!$A$78,AN19<=100,Tablas!$A$79,AN19<=500,Tablas!$A$80,AN19<=999,Tablas!$A$81,AN19>1000,Tablas!T101)} -> #N/A
N20: =VLOOKUP(M20,Tablas!$A$31:$B$38,2,FALSE) -> #N/A | P20: =VLOOKUP(O20,Tablas!$A$41:$B$47,2,FALSE) -> #N/A | R20: =VLOOKUP(Q20,Tablas!$A$51:$B$59,2,FALSE) -> #N/A | T20: =VLOOKUP(S20,Tablas!$A$62:$B$72,2,FALSE) -> #N/A | U20: =N20*P20*R20*T20 -> #N/A | V20: {=_xlfn.IFS(U20<=1,Tablas!$A$75,U20<=5,Tablas!$A$76,U20<=10,Tablas!$A$77,U20<=50,Tablas!$A$78,U20<=100,Tablas!$A$79,U20<=500,Tablas!$A$80,U20<=999,Tablas!$A$81,U20>1000,Tablas!A102)} -> #N/A | W20: {=_xlfn.IFS(V20=Tablas!$A$87,Tablas!$B$87,V20=Tablas!$A$88,Tablas!$B$88,V20=Tablas!$A$89,Tablas!$B$89,V20=Tablas!$A$90,Tablas!$B$90,V20=Tablas!$A$91,Tablas!$B$91,V20=Tablas!$A$92,Tablas!$B$92,V20=Tablas!$A$93,Tablas!$B$93,V20=Tablas!$A$94,Tablas!$B$94)} -> #N/A | AG20: =VLOOKUP(AF20,Tablas!A51:B58,2,FALSE) -> #N/A | AI20: =VLOOKUP(AH20,Tablas!A61:B67,2,FALSE) -> #N/A | AK20: =VLOOKUP(AJ20,Tablas!A71:B79,2,FALSE) -> #N/A | AM20: =VLOOKUP(AL20,Tablas!A82:B92,2,FALSE) -> #N/A | AN20: =AG20*AI20*AK20*AM20 -> #N/A | AO20: {=_xlfn.IFS(AN20<=1,Tablas!$A$75,AN20<=5,Tablas!$A$76,AN20<=10,Tablas!$A$77,AN20<=50,Tablas!$A$78,AN20<=100,Tablas!$A$79,AN20<=500,Tablas!$A$80,AN20<=999,Tablas!$A$81,AN20>1000,Tablas!T102)} -> #N/A
N21: =VLOOKUP(M21,Tablas!$A$31:$B$38,2,FALSE) -> #N/A | P21: =VLOOKUP(O21,Tablas!$A$41:$B$47,2,FALSE) -> #N/A | R21: =VLOOKUP(Q21,Tablas!$A$51:$B$59,2,FALSE) -> #N/A | T21: =VLOOKUP(S21,Tablas!$A$62:$B$72,2,FALSE) -> #N/A | U21: =N21*P21*R21*T21 -> #N/A | V21: {=_xlfn.IFS(U21<=1,Tablas!$A$75,U21<=5,Tablas!$A$76,U21<=10,Tablas!$A$77,U21<=50,Tablas!$A$78,U21<=100,Tablas!$A$79,U21<=500,Tablas!$A$80,U21<=999,Tablas!$A$81,U21>1000,Tablas!A103)} -> #N/A | W21: {=_xlfn.IFS(V21=Tablas!$A$87,Tablas!$B$87,V21=Tablas!$A$88,Tablas!$B$88,V21=Tablas!$A$89,Tablas!$B$89,V21=Tablas!$A$90,Tablas!$B$90,V21=Tablas!$A$91,Tablas!$B$91,V21=Tablas!$A$92,Tablas!$B$92,V21=Tablas!$A$93,Tablas!$B$93,V21=Tablas!$A$94,Tablas!$B$94)} -> #N/A | AG21: =VLOOKUP(AF21,Tablas!A52:B59,2,FALSE) -> #N/A | AI21: =VLOOKUP(AH21,Tablas!A62:B68,2,FALSE) -> #N/A | AK21: =VLOOKUP(AJ21,Tablas!A72:B80,2,FALSE) -> #N/A | AM21: =VLOOKUP(AL21,Tablas!A83:B93,2,FALSE) -> #N/A | AN21: =AG21*AI21*AK21*AM21 -> #N/A | AO21: {=_xlfn.IFS(AN21<=1,Tablas!$A$75,AN21<=5,Tablas!$A$76,AN21<=10,Tablas!$A$77,AN21<=50,Tablas!$A$78,AN21<=100,Tablas!$A$79,AN21<=500,Tablas!$A$80,AN21<=999,Tablas!$A$81,AN21>1000,Tablas!T103)} -> #N/A
... N102: =VLOOKUP(M102,Tablas!$A$31:$B$38,2,FALSE) -> #N/A | P102: =VLOOKUP(O102,Tablas!$A$41:$B$47,2,FALSE) -> #N/A | R102: =VLOOKUP(Q102,Tablas!$A$51:$B$59,2,FALSE) -> #N/A | T102: =VLOOKUP(S102,Tablas!$A$62:$B$72,2,FALSE) -> #N/A | U102: =N102*P102*R102*T102 -> #N/A | V102: {=_xlfn.IFS(U102<=1,Tablas!$A$75,U102<=5,Tablas!$A$76,U102<=10,Tablas!$A$77,U102<=50,Tablas!$A$78,U102<=100,Tablas!$A$79,U102<=500,Tablas!$A$80,U102<=999,Tablas!$A$81,U102>1000,Tablas!A184)} -> #N/A | W102: {=_xlfn.IFS(V102=Tablas!$A$87,Tablas!$B$87,V102=Tablas!$A$88,Tablas!$B$88,V102=Tablas!$A$89,Tablas!$B$89,V102=Tablas!$A$90,Tablas!$B$90,V102=Tablas!$A$91,Tablas!$B$91,V102=Tablas!$A$92,Tablas!$B$92,V102=Tablas!$A$93,Tablas!$B$93,V102=Tablas!$A$94,Tablas!$B$94)} -> #N/A | AG102: =VLOOKUP(AF102,Tablas!A133:B140,2,FALSE) -> #N/A | AI102: =VLOOKUP(AH102,Tablas!A143:B149,2,FALSE) -> #N/A | AK102: =VLOOKUP(AJ102,Tablas!A153:B161,2,FALSE) -> #N/A | AM102: =VLOOKUP(AL102,Tablas!A164:B174,2,FALSE) -> #N/A | AN102: =AG102*AI102*AK102*AM102 -> #N/A | AO102: {=_xlfn.IFS(AN102<=1,Tablas!$A$75,AN102<=5,Tablas!$A$76,AN102<=10,Tablas!$A$77,AN102<=50,Tablas!$A$78,AN102<=100,Tablas!$A$79,AN102<=500,Tablas!$A$80,AN102<=999,Tablas!$A$81,AN102>1000,Tablas!T184)} -> #N/A

Sheet Tablas
B2: Mecanismos de lesión | D2: FE: Frecuencia de Exposición | G2: NP: # de personas en riesgo | J2: G: Gravedad del posible daño/pérdida | M2: P: Probabilidad de Ocurrencia | Q2: HRN | R2: Nivel de Riesgo | S2: Tiempos de acción | U2: Tipos de Tareas | W2: Frecuencia | Y2: Pirámide invertida
B3: 1.- Golpeado Contra (chocar contra) | D3: 0.1 | E3: Infrecuente | J3: 0.1 | K3: Rasguño o raspadura | M3: 0 | N3: Imposible | O3: No puede suceder | Q3: 0-1 | R3: Insignificante | S3: Aceptable
B4: 2.- Golpeado por (golpeado por objeto en movimiento) | D4: 0.2 | E4: Anual | G4: 1 | H4: 1-2 personas | J4: 0.5 | K4: Cortadura o efecto leve a la salud | M4: 0.1 | N4: Casi imposible | O4: Posible en circunstancias extremas | Q4: Más de 1 hasta 5 | R4: Muy Bajo | S4: Menor a un año | U4: Operación Normal | W4: Constantemente | Y4: Eliminar | Z4: La eliminación es el proceso de eliminar el peligro del lugar de trabajo. Es la manera más eficaz de controlar un riesgo porque el peligro ya no está presente. Es la forma preferida de controlar un peligro y debe utilizarse siempre que sea posible.
B5: 3.- Atrapado entre o bajo (aplastados o amputados) | D5: 1 | E5: Mensual | G5: 2 | H5: 3-7 personas | J5: 1 | K5: Fractura de hueso menor (dedos) o enfermedad ocupacional menor temporal | M5: 0.5 | N5: Altamente improbable | O5: Difícil que suceda | Q5: Más de 5 hasta 10 | R5: Bajo | S5: Menor a tres meses | U5: Operación Anormal | W5: Cada hora | Y5: Sustituir | Z5: Reemplazar o reducir la magnitud del riesgo
B6: 4.- Sobrecarga, Sobrepresión, Sobre flexión, Ergonómico | D6: 1.5 | E6: Semanal | G6: 4 | H6: 8-15 personas | J6: 2 | K6: Fractura de hueso mayor (brazo, pierna) o enfermedad ocupacional menor permanente | M6: 1 | N6: Improbable | O6: Pudiera ocurrir | Q6: Más de 10 hasta 50 | R6: Medio | S6: Menor a un mes | U6: Limpieza, lavado / Desincrustados | W6: Diario | Y6: Control de Ingenieria | Z6: Dispositivos de seguridad, automatizar, poka-yokes (se concentran en la fuente del peligro y no en los trabajadores expuestos al peligro)
B7: 5.- Contacto con (electricidad, calor, frio, Radiación, | D7: 2.5 | E7: Diario | G7: 8 | H7: 16-50 personas | J7: 4 | K7: Pérdida de un ojo, un dedo o enfermedad ocupacional seria temporal (LTA) | M7: 2 | N7: Posible | O7: Inusual (han sucedido sustos) | Q7: Más de 50 hasta 100 | R7: alto | S7: Menor a una semana | U7: Rutas LILA | W7: Semanal | Y7: Control Administrativo | Z7: Reglas, procedimientos, politicas, instructivos, gestión visual
B8: cáusticos, tóxicos, biológicos, amoniaco, ruido) | D8: 4 | E8: Cada hora | G8: 12 | H8: >50 personas | J8: 8 | K8: Pérdida de los dos ojos, manos, piernas o enfermedad ocupacional seria permanente | M8: 5 | N8: Alguna probabilidad | O8: Puede pasar (sustos recurrentes) | Q8: Más de 100 hasta 500 | R8: Muy Alto | S8: Menor a un día | U8: Cambios de formato / producto | W8: Mensual | Y8: EPP
B9: 6.- Caída de Diferente Nivel | D9: 5 | E9: Constantemente | J9: 15 | K9: Muerte | M9: 8 | N9: Probable | O9: No sorpresa si ocurre (ha ocurrido un accidente) | Q9: Más de 500 hasta 999 | R9: Extremo | S9: Inmediato | U9: Mantenimientos | W9: Anual
B10: 7.- Caída del mismo nivel | M10: 10 | N10: Muy probable | O10: Se espera que suceda (han ocurrido mas de 1 accidente) | Q10: Mayor o igual a 1000 | R10: Inaceptable | S10: Parar y detener la actividad | U10: Muestreos de Calidad | W10: Infrecuentemente
B11: 8.- Atrapado en (puntos de pellizco) | M11: 15 | N11: Certero | O11: Sin duda sucederá
B12: 9.- Atrapado en (enganchado con, colgado) | Y12: Estandar
B13: 10.- Escapes al ambiente de: Amoniaco, Gas, Sustancias Peligrosas.
Y14: SI
Y15: NO
B17: Mecanismos de lesión | D17: Valor | E17: FE: Frecuencia de Exposición | G17: Valor | H17: NP: # de personas en riesgo | J17: G: Gravedad del posible daño/pérdida | M17: P: Probabilidad de Ocurrencia | Q17: HRN | R17: Nivel de Riesgo | S17: Tiempos de acción | Y17: Plantas
B19: 1.- Golpeado Contra (chocar contra) | D19: 0.1 | E19: Infrecuente | G19: 1 | H19: 1-2 personas | J19: 0.1 | K19: Rasguño o raspadura | M19: 0 | N19: Imposible | O19: No puede suceder | Q19: 0-1 | R19: Insignificante | S19: Aceptable | Y19: Xalostoc
B20: 2.- Golpeado por (golpeado por objeto en movimiento) | D20: 0.2 | E20: Anual | G20: 2 | H20: 3-7 personas | J20: 0.5 | K20: Cortadura o efecto leve a la salud | M20: 0.1 | N20: Casi imposible | O20: Posible en circunstancias extremas | Q20: Más de 1 hasta 5 | R20: Muy Bajo | S20: Menor a un año | Y20: Guadalajara
B21: 3.- Atrapado entre o bajo (aplastados o amputados) | D21: 1 | E21: Mensual | G21: 4 | H21: 8-15 personas | J21: 1 | K21: Fractura de hueso menor (dedos) o enfermedad ocupacional menor temporal | M21: 0.5 | N21: Altamente improbable | O21: Difícil que suceda | Q21: Más de 5 hasta 10 | R21: Bajo | S21: Menor a tres meses | Y21: Noreste
B22: 4.- Sobrecarga, Sobrepresión, Sobre flexión, Ergonómico | D22: 1.5 | E22: Semanal | G22: 8 | H22: 16-50 personas | J22: 2 | K22: Fractura de hueso mayor (brazo, pierna) o enfermedad ocupacional menor permanente | M22: 1 | N22: Improbable | O22: Pudiera ocurrir | Q22: Más de 10 hasta 50 | R22: Medio | S22: Menor a un mes | Y22: Atitalaquia
B23: 5.- Contacto con (electricidad, calor, frio, Radiación, | D23: 2.5 | E23: Diario | G23: 12 | H23: >50 personas | J23: 4 | K23: Pérdida de un ojo, un dedo o enfermedad ocupacional seria temporal (LTA) | M23: 2 | N23: Posible | O23: Inusual (han sucedido sustos) | Q23: Más de 50 hasta 100 | R23: alto | S23: Menor a una semana | Y23: Pénjamo
B24: cáusticos, tóxicos, biológicos, amoniaco, ruido) | D24: 4 | E24: Cada hora | J24: 8 | K24: Pérdida de los dos ojos, manos, piernas o enfermedad ocupacional seria permanente | M24: 5 | N24: Alguna probabilidad | O24: Puede pasar (sustos recurrentes) | Q24: Más de 100 hasta 500 | R24: Muy Alto | S24: Menor a un día | Y24: Chihuahua
B25: 6.- Caída de Diferente Nivel | D25: 5 | E25: Constantemente | J25: 15 | K25: Muerte | M25: 8 | N25: Probable | O25: No sorpresa si ocurre (ha ocurrido un accidente) | Q25: Más de 500 hasta 999 | R25: Extremo | S25: Inmediato | Y25: Tangamanga
B26: 7.- Caída del mismo nivel | M26: 10 | N26: Muy probable | O26: Se espera que suceda (han ocurrido mas de 1 accidente) | Q26: Mayor o igual a 1000 | R26: Inaceptable | S26: Parar y detener la actividad | Y26: Supremo
B27: 8.- Atrapado en (puntos de pellizco) | M27: 15 | N27: Certero | O27: Sin duda sucederá | Y27: Pizzas
B28: 9.- Atrapado en (enganchado con, colgado) | Y28: Saltillo
B29: 10.- Escapes al ambiente de: Amoniaco, Gas, Sustancias Peligrosas. | Y29: Eugenia
Y30: Lagos de Moreno Quesos
A31: FE: Frecuencia de Exposición | B31: Valor | Y31: Lagos de Moreno Yogurt
A32: Infrecuente | B32: 0.1 | Y32: Linares
A33: Anual | B33: 0.2 | Y33: Molino
A34: Mensual | B34: 1 | Y34: Sabinas
A35: Semanal | B35: 1.5 | Y35: Celaya
A36: Diario | B36: 2.5
A37: Cada hora | B37: 4
A38: Constantemente | B38: 5
A41: NP: # de personas en riesgo | B41: Valor
A43: 1-2 personas | B43: 1
A44: 3-7 personas | B44: 2
A45: 8-15 personas | B45: 4
A46: 16-50 personas | B46: 8
...

Sheet Instrucciones-Concepto del HRN
C1: FORMATO PARA REALIZAR EVALUACIONES DE RIESGOS DE UNA TAREA
C2: Nombre Lider: | H2: Puesto de trabajo: | AL2: Fecha de inicio de Elaboración:
B4: Descripción | K4: Contramedidas Existentes | M4: Riesgo Actual | W4: "Prioridad" Tiempo de acción | X4: Plan de Trabajo | AD4: Contramedidas Adicionales | AF4: Riesgo disminuido | AP4: Estandar | AQ4: Marco Normativo
B5: Planta | C5: codigo | D5: Fecha | E5: Área | F5: Descripción de las tareas que componen el puesto | G5: Fotografía de la tarea | H5: Peligros identificados | I5: Mecanismo de lesión (Ligar tabla) | J5: Descripción del Riesgo (pasos+peligros+mecanismos de lesión) | K5: Controles | L5: Defensas | M5: FE | N5: Valor | O5: NP | P5: Valor | Q5: G | R5: Valor | S5: P | T5: Valor | U5: HRN | V5: Nivel de riesgo | X5: Plan de acción (¿Qué y el cómo?) | Y5: Fecha programada | Z5: Piramide de Contramedidas | AA5: Responsable | AB5: Fecha Cierre | AC5: Estatus | AD5: Controles | AE5: Defensas | AF5: FE | AG5: Valor | AH5: NP | AI5: Valor | AJ5: G | AK5: Valor | AL5: P | AM5: Valor | AN5: HRN | AO5: Nivel de riesgo | AP5: Implementado en Gemba | AQ5: Normativa

Sheet Tablas de cálculo
B1: Tabla de índices para calcular HRN
B3: P: Probabilidad de Ocurrencia | F3: FE: Frecuencia de Exposición | J3: Pirámide invertida
B4: 0 | C4: Imposible | D4: No puede suceder | F4: 0.1 | G4: Infrecuente
B5: 0.1 | C5: Casi imposible | D5: Posible en circunstancias extremas | F5: 0.2 | G5: Anual | J5: Eliminar | K5: La eliminación es el proceso de eliminar el peligro del lugar de trabajo. Es la manera más eficaz de controlar un riesgo porque el peligro ya no está presente. Es la forma preferida de controlar un peligro y debe utilizarse siempre que sea posible.
B6: 0.5 | C6: Altamente improbable | D6: Difícil que suceda | F6: 1 | G6: Mensual | J6: Sustituir | K6: Reemplazar o reducir la magnitud del riesgo
B7: 1 | C7: Improbable | D7: Pudiera ocurrir | F7: 1.5 | G7: Semanal | J7: Control de Ingenieria | K7: Dispositivos de seguridad, automatizar, poka-yokes (se concentran en la fuente del peligro y no en los trabajadores expuestos al peligro)
B8: 2 | C8: Posible | D8: Inusual (han sucedido sustos) | F8: 2.5 | G8: Diario | J8: Control Administrativo | K8: Reglas, procedimientos, politicas, instructivos, gestión visual
B9: 5 | C9: Alguna probabilidad | D9: Puede pasar (sustos recurrentes) | F9: 4 | G9: Cada hora | J9: EPP
B10: 8 | C10: Probable | D10: No sorpresa si ocurre (ha ocurrido un accidente) | F10: 5 | G10: Constantemente
B11: 10 | C11: Muy probable | D11: Se espera que suceda (han ocurrido mas de 1 accidente)
B12: 15 | C12: Certero | D12: Sin duda sucederá
B14: G: Gravedad del posible daño/pérdida | F14: NP: # de personas en riesgo
B15: 0.1 | C15: Rasguño o raspadura | F15: 1 | G15: 1-2 personas
B16: 0.5 | C16: Cortadura o efecto leve a la salud | F16: 2 | G16: 3-7 personas
B17: 1 | C17: Fractura de hueso menor (dedos) o enfermedad ocupacional menor temporal | F17: 4 | G17: 8-15 personas
B18: 2 | C18: Fractura de hueso mayor (brazo, pierna) o enfermedad ocupacional menor permanente | F18: 8 | G18: 16-50 personas
B19: 4 | C19: Pérdida de un ojo, un dedo o enfermedad ocupacional seria temporal (LTA) | F19: 12 | G19: >50 personas
B20: 8 | C20: Pérdida de los dos ojos, manos, piernas o enfermedad ocupacional seria permanente | F20: HRN= P x G x FE x NP
B21: 15 | C21: Muerte
B44: Mecanismos de Lesión
B46: 1.- Golpeado Contra (chocar contra) | E46: 6.- Caída de Diferente Nivel
B47: 2.- Golpeado por (golpeado por objeto en movimiento) | E47: 7.- Caída del mismo nivel
B48: 3.- Atrapado entre o bajo (aplastados o amputados) | E48: 8.- Atrapado en (puntos de pellizco)
B49: 4.- Sobrecarga, Sobrepresión, Sobre flexión, Ergonómico | E49: 9.- Atrapado en (enganchado con, colgado)
B50: 5.- Contacto con (electricidad, calor, frio, Radiación, | E50: 10.- Escapes al ambiente de: Amoniaco, Gas, Sustancias Peligrosas.
B51: cáusticos, tóxicos, biológicos, amoniaco, ruido)

Sheet Catálogo Peligros
A2: Catalogo de peligros y consecuencias
A4: Tipo | B4: Peligros | G4: Consecuencias
A5: Biológicos | B5: Bacterias / Virus | G5: Amputación | H5: Fatiga muscular
A6: Biológicos | B6: Biológico infeccioso | G6: Dolor de cabeza | H6: Fractura
A7: Biológicos | B7: Enfermedades por alimentos y bebidas | G7: Conjuntivitis irritativa | H7: Herida cortante
A8: Biológicos | B8: Higiene (facilidades sanitarias, disposición de desechos, etc..) | G8: Deshidratación | H8: Herida penetrante
A9: Biológicos | B9: Sangre | G9: Dermatitis/Inflamacion de la piel | H9: Disminución de audición
A10: Biológicos | B10: Vida salvaje (animales, insectos, plantas, etc.) | G10: Desorden de trauma acumulativo | H10: Intoxicación
A11: Ergonómicos | B11: Agotamiento excesivo | G11: Diarrea | H11: Lesión por cuerpo extraño
A12: Ergonómicos | B12: Asientos inapropiados | G12: Dificultad respiratoria | H12: Dolor de espalda o cintura
A13: Ergonómicos | B13: Jalar o empujar | G13: Disminución de la vista | H13: Luxación
A14: Ergonómicos | B14: Levantamiento de cargas pesadas manuales | G14: Enfermedades endémicas / epidémicas | H14: Aplastamiento o Compresion
A15: Ergonómicos | B15: Materiales de trabajo | G15: Otra enfermedad ocupacional | H15: Mareo
A16: Ergonómicos | B16: Movimientos repetitivos | G16: Sangrado de nariz | H16: Muerte
... A26: Especiales | B26: Otros | G26: Incendio o explosion | H26: Derrame
A27: Físicos | B27: Cargas electrostáticas
A28: Físicos | B28: Contacto con objetos contusos
A29: Físicos | B29: Iluminación
A30: Físicos | B30: Pantalla de visualización de datos PVD's
A31: Físicos | B31: Partes eléctricas vivas
A32: Físicos | B32: Radiaciones ionizantes y no ionizantes
A33: Físicos | B33: Ruido
A34: Físicos | B34: Temperaturas abatidas (frio o calor)
A35: Físicos | B35: Temperaturas en el ambiente de trabajo / Ventilación inadecuada
A36: Físicos | B36: Vibración
A37: Fuego | B37: Fuentes de combustible (materiales combustibles o inflamables)
A38: Fuego | B38: Fuentes de ignición (calor, eléctricos, etc..)
... A60: Químicos | B60: Tóxico

Sheet Contr & Def
A1: Controles Tipicos | D1: Defensas Tipicas
B2: Controles de ingenieria (estándars específicos) y relacionados a condiciones de equipos
A3: Guarda con Microswitch de seguridad | D3: Paros de emergencia
A4: Guardas Fijas de seguridad | D4: uso de casco de seguridad dielectrico
A5: Guardas de Seguridad autoajustables | D5: Uso de calzado de seguridad
A6: Cortinas de Luz | B6: 1.-Uso de equipo 2.-Capacitacion en Politica de Seguridad 3.-Capacitacion en Politica de pisos limpios 4.-Capcitacion de Reglas de Seguridad Generales 5.-LESE I 11 046 Levantamiento seguro de Cargas Pesadas.doco 6.-Realizacion de Calrentamiento y/o gimnasia laoboral 7.-Rotacion de puestos de trabajo8.-Barreras, contenciones , delimitaciones | D6: Uso de faja de soporte lumbar | F6: 1.-Uso de faja de soporte lumbar 2.-Uso de bota de PVC sanitaria 3.-Brigadas de emergencia 4.-Vigilancia Medica 5.-Brigadas de primeros auxilios
A7: Aislante térmicos | B7: 8.-Barreras, contenciones , delimitaciones | D7: Uso de guante para químico
A8: Señalización de riesgos | D8: Uso de guante para temperaturas bajas
A9: Señalizacion de Tuberias | D9: Uso de guante para temperaturas altas
A10: Uso de cutter de sEguridad modelo XXXXXXXX | D10: Uso de guante anticorte
A11: Controles visulaes de los controles del equipo | D11: Uso de guante anti-impacto
A12: Piso o tapete antiderrapante | D12: Uso de mascarilla de protección respiratoria
A13: Tapete ergonómico | D13: Uso de careta de protección facial
A14: Escaleras en buenas condiciones | D14: Uso de careta de soldador
A15: Tableros eléctricos cerrados | D15: Uso de conchas auditivas
A16: Cables electricos aislados | D16: Uso de tapones auditivos
A17: Dispositivos de control de presión de aire comprimido | D17: Uso de lentes de seguridad
A18: Iluminación Focalizada para cierta actividad | D18: Uso de googles de seguridad
A19: Guardas Acusticas | D19: Uso de guantes para soldador
... A25: dispositivosque controlan la velocidad, presion, temperatura, etc | D25: Brigadas de primeros auxilios
B26: Controles Administrativos (matriz de habilidades) | D26: Regaderas y lavaojos de emergencia
A27: Capacitacion en Politica de Seguridad | D27: Vigilancia Medica
A28: Capacitacion en Politica de pisos limpios | D28: Colocación de material blando en puntos de riesgo de golpear contra.
A29: Capacitacion en reglas de oro | D29: Uso de canilleras
A30: Capcitacion de Reglas de Seguridad Generales | D30: Uso de coderas
A31: Capacitacion en procedimientos especificos como: | D31: Uso de casco de seguridad con barbiquejo
A32: LESE I 11 046 Levantamiento seguro de Cargas Pesadas.doco | D32: Uso de uniforme de mezclilla para soldador
A33: LESE P 11 005 Bloqueo de Energias.doc | D33: Uso de traje tipo tybek
A34: LESE I 11 047 Uso y Manejo del Cutter Opticut.doc | D34: Uso de traje de bombero
